<?xml version="1.0"?>
<robot name="ackermann_vehicle" xmlns:xacro="http://ros.org/wiki/xacro">
  
  <!-- 材质定义 -->
  <material name="blue">
    <color rgba="0 0 0.8 1"/>
  </material>
  
  <material name="black">
    <color rgba="0.1 0.1 0.1 1"/>
  </material>
  
  <material name="white">
    <color rgba="1 1 1 1"/>
  </material>
  
  <material name="red">
    <color rgba="0.8 0 0 1"/>
  </material>

  <!-- 车身主体 -->
  <link name="base_link">
    <visual>
      <geometry>
        <box size="2.0 1.0 0.5"/>
      </geometry>
      <material name="blue"/>
    </visual>
    <collision>
      <geometry>
        <box size="2.0 1.0 0.5"/>
      </geometry>
    </collision>
    <inertial>
      <mass value="500"/>
      <inertia ixx="83.33" ixy="0" ixz="0" iyy="166.67" iyz="0" izz="83.33"/>
    </inertial>
  </link>

  <!-- 前轴 -->
  <link name="front_axle">
    <visual>
      <geometry>
        <cylinder radius="0.05" length="1.2"/>
      </geometry>
      <material name="black"/>
    </visual>
    <collision>
      <geometry>
        <cylinder radius="0.05" length="1.2"/>
      </geometry>
    </collision>
    <inertial>
      <mass value="20"/>
      <inertia ixx="0.6" ixy="0" ixz="0" iyy="0.6" iyz="0" izz="0.6"/>
    </inertial>
  </link>

  <!-- 后轴 -->
  <link name="rear_axle">
    <visual>
      <geometry>
        <cylinder radius="0.05" length="1.2"/>
      </geometry>
      <material name="black"/>
    </visual>
    <collision>
      <geometry>
        <cylinder radius="0.05" length="1.2"/>
      </geometry>
    </collision>
    <inertial>
      <mass value="20"/>
      <inertia ixx="0.6" ixy="0" ixz="0" iyy="0.6" iyz="0" izz="0.6"/>
    </inertial>
  </link>

  <!-- 前左轮 -->
  <link name="front_left_wheel">
    <visual>
      <geometry>
        <cylinder radius="0.3" length="0.1"/>
      </geometry>
      <material name="black"/>
    </visual>
    <collision>
      <geometry>
        <cylinder radius="0.3" length="0.1"/>
      </geometry>
    </collision>
    <inertial>
      <mass value="15"/>
      <inertia ixx="0.675" ixy="0" ixz="0" iyy="0.675" iyz="0" izz="0.675"/>
    </inertial>
  </link>

  <!-- 前右轮 -->
  <link name="front_right_wheel">
    <visual>
      <geometry>
        <cylinder radius="0.3" length="0.1"/>
      </geometry>
      <material name="black"/>
    </visual>
    <collision>
      <geometry>
        <cylinder radius="0.3" length="0.1"/>
      </geometry>
    </collision>
    <inertial>
      <mass value="15"/>
      <inertia ixx="0.675" ixy="0" ixz="0" iyy="0.675" iyz="0" izz="0.675"/>
    </inertial>
  </link>

  <!-- 后左轮 -->
  <link name="rear_left_wheel">
    <visual>
      <geometry>
        <cylinder radius="0.3" length="0.1"/>
      </geometry>
      <material name="black"/>
    </visual>
    <collision>
      <geometry>
        <cylinder radius="0.3" length="0.1"/>
      </geometry>
    </collision>
    <inertial>
      <mass value="15"/>
      <inertia ixx="0.675" ixy="0" ixz="0" iyy="0.675" iyz="0" izz="0.675"/>
    </inertial>
  </link>

  <!-- 后右轮 -->
  <link name="rear_right_wheel">
    <visual>
      <geometry>
        <cylinder radius="0.3" length="0.1"/>
      </geometry>
      <material name="black"/>
    </visual>
    <collision>
      <geometry>
        <cylinder radius="0.3" length="0.1"/>
      </geometry>
    </collision>
    <inertial>
      <mass value="15"/>
      <inertia ixx="0.675" ixy="0" ixz="0" iyy="0.675" iyz="0" izz="0.675"/>
    </inertial>
  </link>

  <!-- 转向连杆 -->
  <link name="steering_link">
    <visual>
      <geometry>
        <box size="0.1 0.8 0.1"/>
      </geometry>
      <material name="red"/>
    </visual>
    <collision>
      <geometry>
        <box size="0.1 0.8 0.1"/>
      </geometry>
    </collision>
    <inertial>
      <mass value="5"/>
      <inertia ixx="0.267" ixy="0" ixz="0" iyy="0.267" iyz="0" izz="0.267"/>
    </inertial>
  </link>

  <!-- 前轴到车身的关节 -->
  <joint name="front_axle_joint" type="fixed">
    <parent link="base_link"/>
    <child link="front_axle"/>
    <origin xyz="0.8 0 0" rpy="0 0 0"/>
  </joint>

  <!-- 后轴到车身的关节 -->
  <joint name="rear_axle_joint" type="fixed">
    <parent link="base_link"/>
    <child link="rear_axle"/>
    <origin xyz="-0.8 0 0" rpy="0 0 0"/>
  </joint>

  <!-- 前左轮到前轴的关节 -->
  <joint name="front_left_wheel_joint" type="continuous">
    <parent link="front_axle"/>
    <child link="front_left_wheel"/>
    <origin xyz="0 0.65 0" rpy="0 0 0"/>
    <axis xyz="0 0 1"/>
    <limit effort="100" velocity="10" lower="-3.14" upper="3.14"/>
  </joint>

  <!-- 前右轮到前轴的关节 -->
  <joint name="front_right_wheel_joint" type="continuous">
    <parent link="front_axle"/>
    <child link="front_right_wheel"/>
    <origin xyz="0 -0.65 0" rpy="0 0 0"/>
    <axis xyz="0 0 1"/>
    <limit effort="100" velocity="10" lower="-3.14" upper="3.14"/>
  </joint>

  <!-- 后左轮到后轴的关节 -->
  <joint name="rear_left_wheel_joint" type="continuous">
    <parent link="rear_axle"/>
    <child link="rear_left_wheel"/>
    <origin xyz="0 0.65 0" rpy="0 0 0"/>
    <axis xyz="0 0 1"/>
    <limit effort="100" velocity="10" lower="-3.14" upper="3.14"/>
  </joint>

  <!-- 后右轮到后轴的关节 -->
  <joint name="rear_right_wheel_joint" type="continuous">
    <parent link="rear_axle"/>
    <child link="rear_right_wheel"/>
    <origin xyz="0 -0.65 0" rpy="0 0 0"/>
    <axis xyz="0 0 1"/>
    <limit effort="100" velocity="10" lower="-3.14" upper="3.14"/>
  </joint>

  <!-- 转向连杆到前轴的关节 -->
  <joint name="steering_joint" type="revolute">
    <parent link="front_axle"/>
    <child link="steering_link"/>
    <origin xyz="0 0 0" rpy="0 0 0"/>
    <axis xyz="0 0 1"/>
    <limit effort="100" velocity="2" lower="-0.5" upper="0.5"/>
  </joint>

  <!-- Gazebo插件配置 -->
  <gazebo>
    <plugin name="ackermann_control" filename="libgazebo_ros_ackermann_drive.so">
      <commandTopic>cmd_vel</commandTopic>
      <odometryTopic>odom</odometryTopic>
      <odometryFrame>odom</odometryFrame>
      <robotBaseFrame>base_link</robotBaseFrame>
      <robotNamespace>/ackermann</robotNamespace>
      <wheelSeparation>1.3</wheelSeparation>
      <wheelDiameter>0.6</wheelDiameter>
      <wheelAcceleration>1.0</wheelAcceleration>
      <wheelTorque>20</wheelTorque>
      <rosDebugLevel>na</rosDebugLevel>
      <leftJoint>rear_left_wheel_joint</leftJoint>
      <rightJoint>rear_right_wheel_joint</rightJoint>
      <leftSteeringJoint>steering_joint</leftSteeringJoint>
      <rightSteeringJoint>steering_joint</rightSteeringJoint>
      <wheelbase>1.6</wheelbase>
      <wheelTrack>1.3</wheelTrack>
      <maxSteer>0.5</maxSteer>
    </plugin>
  </gazebo>

  <!-- 轮子的摩擦系数 -->
  <gazebo reference="front_left_wheel">
    <mu1>0.8</mu1>
    <mu2>0.8</mu2>
  </gazebo>
  
  <gazebo reference="front_right_wheel">
    <mu1>0.8</mu1>
    <mu2>0.8</mu2>
  </gazebo>
  
  <gazebo reference="rear_left_wheel">
    <mu1>0.8</mu1>
    <mu2>0.8</mu2>
  </gazebo>
  
  <gazebo reference="rear_right_wheel">
    <mu1>0.8</mu1>
    <mu2>0.8</mu2>
  </gazebo>

</robot>
